Performing system checks...

Unhandled exception in thread started by <function check_errors.<locals>.wrapper at 0x7f20478b2620>
Traceback (most recent call last):
  File "/home/chris/courses/django-workshop/venv/lib/python3.5/site-packages/django/utils/autoreload.py", line 228, in wrapper
    fn(*args, **kwargs)
  File "/home/chris/courses/django-workshop/venv/lib/python3.5/site-packages/django/core/management/commands/runserver.py", line 125, in inner_run
    self.check(display_num_errors=True)
  File "/home/chris/courses/django-workshop/venv/lib/python3.5/site-packages/django/core/management/base.py", line 359, in check
    include_deployment_checks=include_deployment_checks,
  File "/home/chris/courses/django-workshop/venv/lib/python3.5/site-packages/django/core/management/base.py", line 346, in _run_checks
    return checks.run_checks(**kwargs)
  File "/home/chris/courses/django-workshop/venv/lib/python3.5/site-packages/django/core/checks/registry.py", line 81, in run_checks
    new_errors = check(app_configs=app_configs)
  File "/home/chris/courses/django-workshop/venv/lib/python3.5/site-packages/django/core/checks/urls.py", line 16, in check_url_config
    return check_resolver(resolver)
  File "/home/chris/courses/django-workshop/venv/lib/python3.5/site-packages/django/core/checks/urls.py", line 26, in check_resolver
    return check_method()
  File "/home/chris/courses/django-workshop/venv/lib/python3.5/site-packages/django/urls/resolvers.py", line 254, in check
    for pattern in self.url_patterns:
  File "/home/chris/courses/django-workshop/venv/lib/python3.5/site-packages/django/utils/functional.py", line 35, in __get__
    res = instance.__dict__[self.name] = self.func(instance)
  File "/home/chris/courses/django-workshop/venv/lib/python3.5/site-packages/django/urls/resolvers.py", line 405, in url_patterns
    patterns = getattr(self.urlconf_module, "urlpatterns", self.urlconf_module)
  File "/home/chris/courses/django-workshop/venv/lib/python3.5/site-packages/django/utils/functional.py", line 35, in __get__
    res = instance.__dict__[self.name] = self.func(instance)
  File "/home/chris/courses/django-workshop/venv/lib/python3.5/site-packages/django/urls/resolvers.py", line 398, in urlconf_module
    return import_module(self.urlconf_name)
  File "/home/chris/courses/django-workshop/venv/lib/python3.5/importlib/__init__.py", line 126, in import_module
    return _bootstrap._gcd_import(name[level:], package, level)
  File "<frozen importlib._bootstrap>", line 986, in _gcd_import
  File "<frozen importlib._bootstrap>", line 969, in _find_and_load
  File "<frozen importlib._bootstrap>", line 958, in _find_and_load_unlocked
  File "<frozen importlib._bootstrap>", line 673, in _load_unlocked
  File "<frozen importlib._bootstrap_external>", line 673, in exec_module
  File "<frozen importlib._bootstrap>", line 222, in _call_with_frames_removed
  File "/home/chris/courses/django-workshop/cookbook/cookbook/urls.py", line 25, in <module>
    url(r'^recipe/(?P<slug>[-\w]+)/$', recipes.views.detail),
AttributeError: module 'recipes.views' has no attribute 'detail'